Workbook
Name ATLAS_MARKET_CAP_NOVA: 'Trading_Comps'!$C$7
Name ATLAS_EV_NOVA: 'Trading_Comps'!$D$7
Name ATLAS_COMPS_MEDIAN_EV_EBITDA_27: 'Trading_Comps'!$H$18
Name ATLAS_IMPLIED_EV_COMPS: 'Trading_Comps'!$D$24
Name ATLAS_IMPLIED_EQUITY_COMPS: 'Trading_Comps'!$D$29
Name ATLAS_IMPLIED_PRICE_COMPS: 'Trading_Comps'!$D$31
Name ATLAS_WACC: DCF!$D$16
Name ATLAS_UFCF_26: DCF!$D$30
Name ATLAS_UFCF_27: DCF!$E$30
Name ATLAS_UFCF_28: DCF!$F$30
Name ATLAS_UFCF_29: DCF!$G$30
Name ATLAS_UFCF_30: DCF!$H$30
Name ATLAS_DCF_PV_FCF: DCF!$D$40
Name ATLAS_DCF_PV_TV: DCF!$D$41
Name ATLAS_DCF_EV: DCF!$D$42
Name ATLAS_DCF_EQUITY: DCF!$D$47
Name ATLAS_DCF_PRICE: DCF!$D$49
Name ATLAS_MODEL_CHECK: Checks!$D$18

Sheet Cover
B2: PROJECT ATLAS
B3: Analyse de valorisation préliminaire
B6: Cible | C6: Atlas Consumer Group
B7: Secteur | C7: Consommation / Produits de marque
B8: Géographie | C8: Europe
B9: Devise | C9: EUR — montants en M€
B10: Stade | C10: Préparation sell-side — phase amont
B11: Préparé pour | C11: Emma Roberts, Associate
B12: Préparé par | C12: Analyste
B13: Version du cas | C13: project_atlas_v1 · 1.1.0
B16: CONVENTIONS
B17: Bleu | C17: saisie en dur (hypothèse)
B18: Noir | C18: formule
B19: Vert | C19: lien depuis un autre onglet
B21: Ce classeur est un exercice pédagogique. Société et données entièrement fictives.

Sheet Instructions
B2: INSTRUCTIONS
B4: 1. | C4: Complète l'onglet Trading_Comps : market cap, enterprise value et les six multiples de chaque comparable.
B5: 2. | C5: Renseigne les statistiques (min, Q1, médiane, Q3, max) sous le tableau des comps.
B6: 3. | C6: Applique la médiane EV/EBITDA FY27E à l'EBITDA FY27E d'Atlas, puis déroule le bridge jusqu'au prix par action.
B7: 4. | C7: Complète l'onglet DCF : EBIT, impôt, NOPAT, UFCF sur FY26E-FY30E.
B8: 5. | C8: Construis le WACC à partir des hypothèses (CAPM puis pondération).
B9: 6. | C9: Actualise les flux (convention mi-année), calcule la valeur terminale par Gordon, puis l'EV, l'equity et le prix.
B10: 7. | C10: Remplis la table de sensibilité WACC × croissance terminale.
B11: 8. | C11: Reporte les fourchettes dans Valuation_Summary.
B12: 9. | C12: Vérifie que l'onglet Checks affiche MODEL CHECK = OK.
B13: 10. | C13: Enregistre le fichier au format .xlsx et dépose-le sur la plateforme.
C16: Les cellules à compléter sont surlignées en jaune pâle. Utilise des FORMULES : un chiffre saisi en dur ne reçoit qu'un crédit partiel.
C18: Important : enregistre depuis Excel (ou LibreOffice) pour que les formules soient recalculées avant l'envoi.

Sheet Atlas_Raw
B2: ATLAS CONSUMER GROUP — DONNÉES FINANCIÈRES
B3: EUR en millions · A = réalisé, E = plan d'affaires
B5: Exercice | C5: FY23A | D5: FY24A | E5: FY25A | F5: FY26E | G5: FY27E | H5: FY28E | I5: FY29E | J5: FY30E
B6: Chiffre d'affaires | C6: 742 | D6: 798.5 | E6: 841.2 | F6: 892 | G6: 945.5 | H6: 996 | I6: 1041 | J6: 1082.6
B7: Croissance (%) | C7: n.a. | D7: =D6/C6-1 -> 0.076145553 | E7: =E6/D6-1 -> 0.053475266 | F7: =F6/E6-1 -> 0.060389919 | G7: =G6/F6-1 -> 0.059977578 | H7: =H6/G6-1 -> 0.053410894 | I7: =I6/H6-1 -> 0.045180723 | J7: =J6/I6-1 -> 0.039961575
B8: EBITDA | C8: 118.7 | D8: 133.6 | E8: 145.5 | F8: 158.8 | G8: 172.1 | H8: 184.3 | I8: 194.7 | J8: 204.6
B9: Marge d'EBITDA (%) | C9: =C8/C6 -> 0.15997305 | D9: =D8/D6 -> 0.16731371 | E9: =E8/E6 -> 0.17296719 | F9: =F8/F6 -> 0.17802691 | G9: =G8/G6 -> 0.1820201 | H9: =H8/H6 -> 0.18504016 | I9: =I8/I6 -> 0.1870317 | J9: =J8/J6 -> 0.18898947
B10: Dotations aux amortissements (D&A) | C10: 29.7 | D10: 31.1 | E10: 32.8 | F10: 34.8 | G10: 36.9 | H10: 38.8 | I10: 40.6 | J10: 42.2
B11: EBIT | C11: =C8-C10 -> 89 | D11: =D8-D10 -> 102.5 | E11: =E8-E10 -> 112.7 | F11: =F8-F10 -> 124 | G11: =G8-G10 -> 135.2 | H11: =H8-H10 -> 145.5 | I11: =I8-I10 -> 154.1 | J11: =J8-J10 -> 162.4
B12: Investissements (capex) | C12: 31.2 | D12: 33.5 | E12: 35.3 | F12: 37.5 | G12: 39.7 | H12: 41.8 | I12: 43.7 | J12: 45.5
B13: Variation du BFR | C13: 7.4 | D13: 5.7 | E13: 4.3 | F13: 5.1 | G13: 5.4 | H13: 5.1 | I13: 4.5 | J13: 4.2
B16: STRUCTURE DE CAPITAL (au dernier arrêté FY25A)
B17: Trésorerie et équivalents | C17: 68.4
B18: Dette financière brute | C18: 315
B19: Dettes de loyers (IFRS 16) | C19: 84.5
B20: Intérêts minoritaires | C20: 22
B21: Nombre d'actions diluées (m) | C21: 48.6
B22: Taux d'impôt | C22: 0.26

Sheet Comps_Raw
B2: COMPARABLES BOURSIERS — DONNÉES BRUTES
B3: Cours au 31/12/2025 · montants en M€ · consensus de place (fictif)
B5: Société | C5: Cours (€) | D5: Actions dil. (m) | E5: Trésorerie | F5: Dette | G5: Dettes loyers | H5: Minoritaires | I5: CA FY25 | J5: CA FY26E | K5: CA FY27E | L5: EBITDA FY25 | M5: EBITDA FY26E | N5: EBITDA FY27E | O5: EBIT FY25 | P5: EBIT FY26E | Q5: EBIT FY27E
B6: Nova Brands | C6: 42.8 | D6: 96.2 | E6: 121 | F6: 640 | G6: 152 | H6: 18 | I6: 1980 | J6: 2079 | K6: 2172.6 | L6: 356.4 | M6: 385 | N6: 410.6 | O6: 267.3 | P6: 291.1 | Q6: 312.1
B7: Everest Consumer | C7: 28.15 | D7: 145 | E7: 88 | F7: 720 | G7: 118 | H7: 0 | I7: 2310 | J7: 2402.4 | K7: 2486.5 | L7: 392.7 | M7: 414.4 | N7: 435.1 | O7: 289.6 | P7: 308.9 | Q7: 326.3
B8: Northstar Products | C8: 61.4 | D8: 52.8 | E8: 54 | F8: 385 | G8: 66 | H8: 12 | I8: 1104 | J8: 1181.3 | K8: 1252.2 | L8: 210 | M8: 229.2 | N8: 247.9 | O8: 163.8 | P8: 180 | Q8: 195.8
B9: Velora Group | C9: 9.6 | D9: 210 | E9: 42 | F9: 980 | G9: 205 | H9: 34 | I9: 2650 | J9: 2676.5 | K9: 2690 | L9: 397.5 | M9: 388.1 | N9: 376.6 | O9: 278.3 | P9: 267.7 | Q9: 255.6
B10: Prime Household | C10: 35.6 | D10: 78.4 | E10: 96 | F10: 410 | G10: 74 | H10: 8 | I10: 1385 | J10: 1468.1 | K10: 1548.8 | L10: 249.3 | M10: 268.6 | N10: 287.1 | O10: 194 | P10: 211 | Q10: 227.3
B11: Meridian Brands | C11: 54.25 | D11: 63.5 | E11: 73 | F11: 495 | G11: 92 | H11: 15 | I11: 1512 | J11: 1602.7 | K11: 1690.9 | L11: 279.7 | M11: 302.9 | N11: 324.6 | O11: 215.2 | P11: 235.6 | Q11: 254.9
B12: Orion Consumer | C12: 23.7 | D12: 118 | E12: 61 | F12: 528 | G12: 103 | H12: 0 | I12: 1740 | J12: 1809.6 | K12: 1881.9 | L12: 295.8 | M12: 312.1 | N12: 329.3 | O12: 217.5 | P12: 231.6 | Q12: 246.5
B13: Summit Products | C13: 78.9 | D13: 34.2 | E13: 38 | F13: 268 | G13: 47 | H13: 6 | I13: 826 | J13: 891.1 | K13: 954.2 | L13: 165.2 | M13: 181.8 | N13: 197.5 | O13: 132.2 | P13: 146.5 | Q13: 160.1
B16: Note : les données de plan proviennent du consensus. Vérifie la cohérence des périmètres avant de retenir un comparable.

Sheet Trading_Comps
B2: TRADING COMPARABLES
B3: Enterprise value = market cap + dette + dettes de loyers + minoritaires − trésorerie
B6: Société | C6: Market cap | D6: Enterprise value | E6: EV/CA FY26E | F6: EV/CA FY27E | G6: EV/EBITDA FY26E | H6: EV/EBITDA FY27E | I6: EV/EBIT FY26E | J6: EV/EBIT FY27E
B7: Nova Brands | C7: =Comps_Raw!C6*Comps_Raw!D6 -> 4117.36 | D7: =C7+Comps_Raw!F6+Comps_Raw!G6+Comps_Raw!H6-Comps_Raw!E6 -> 4806.36 | E7: =D7/Comps_Raw!J6 -> 2.3118615 | F7: =D7/Comps_Raw!K6 -> 2.2122618 | G7: =D7/Comps_Raw!M6 -> 12.484052 | H7: =D7/Comps_Raw!N6 -> 11.705699 | I7: =D7/Comps_Raw!P6 -> 16.511027 | J7: =D7/Comps_Raw!Q6 -> 15.400064
B8: Everest Consumer | C8: =Comps_Raw!C7*Comps_Raw!D7 -> 4081.75 | D8: =C8+Comps_Raw!F7+Comps_Raw!G7+Comps_Raw!H7-Comps_Raw!E7 -> 4831.75 | E8: =D8/Comps_Raw!J7 -> 2.0112179 | F8: =D8/Comps_Raw!K7 -> 1.9431932 | G8: =D8/Comps_Raw!M7 -> 11.659628 | H8: =D8/Comps_Raw!N7 -> 11.104918 | I8: =D8/Comps_Raw!P7 -> 15.641793 | J8: =D8/Comps_Raw!Q7 -> 14.807692
B9: Northstar Products | C9: =Comps_Raw!C8*Comps_Raw!D8 -> 3241.92 | D9: =C9+Comps_Raw!F8+Comps_Raw!G8+Comps_Raw!H8-Comps_Raw!E8 -> 3650.92 | E9: =D9/Comps_Raw!J8 -> 3.0905951 | F9: =D9/Comps_Raw!K8 -> 2.9156045 | G9: =D9/Comps_Raw!M8 -> 15.92897 | H9: =D9/Comps_Raw!N8 -> 14.72739 | I9: =D9/Comps_Raw!P8 -> 20.282889 | J9: =D9/Comps_Raw!Q8 -> 18.64617
B10: Velora Group | C10: =Comps_Raw!C9*Comps_Raw!D9 -> 2016 | D10: =C10+Comps_Raw!F9+Comps_Raw!G9+Comps_Raw!H9-Comps_Raw!E9 -> 3193 | E10: =D10/Comps_Raw!J9 -> 1.1929759 | F10: =D10/Comps_Raw!K9 -> 1.1869888 | G10: =D10/Comps_Raw!M9 -> 8.227261 | H10: =D10/Comps_Raw!N9 -> 8.4784918 | I10: =D10/Comps_Raw!P9 -> 11.927531 | J10: =D10/Comps_Raw!Q9 -> 12.492175
B11: Prime Household | C11: =Comps_Raw!C10*Comps_Raw!D10 -> 2791.04 | D11: =C11+Comps_Raw!F10+Comps_Raw!G10+Comps_Raw!H10-Comps_Raw!E10 -> 3187.04 | E11: =D11/Comps_Raw!J10 -> 2.1708603 | F11: =D11/Comps_Raw!K10 -> 2.0577479 | G11: =D11/Comps_Raw!M10 -> 11.865376 | H11: =D11/Comps_Raw!N10 -> 11.100801 | I11: =D11/Comps_Raw!P10 -> 15.104455 | J11: =D11/Comps_Raw!Q10 -> 14.021293
B12: Meridian Brands | C12: =Comps_Raw!C11*Comps_Raw!D11 -> 3444.875 | D12: =C12+Comps_Raw!F11+Comps_Raw!G11+Comps_Raw!H11-Comps_Raw!E11 -> 3973.875 | E12: =D12/Comps_Raw!J11 -> 2.4794877 | F12: =D12/Comps_Raw!K11 -> 2.3501538 | G12: =D12/Comps_Raw!M11 -> 13.119429 | H12: =D12/Comps_Raw!N11 -> 12.242375 | I12: =D12/Comps_Raw!P11 -> 16.867042 | J12: =D12/Comps_Raw!Q11 -> 15.589937
B13: Orion Consumer | C13: =Comps_Raw!C12*Comps_Raw!D12 -> 2796.6 | D13: =C13+Comps_Raw!F12+Comps_Raw!G12+Comps_Raw!H12-Comps_Raw!E12 -> 3366.6 | E13: =D13/Comps_Raw!J12 -> 1.8604111 | F13: =D13/Comps_Raw!K12 -> 1.7889367 | G13: =D13/Comps_Raw!M12 -> 10.786927 | H13: =D13/Comps_Raw!N12 -> 10.223504 | I13: =D13/Comps_Raw!P12 -> 14.536269 | J13: =D13/Comps_Raw!Q12 -> 13.657606
B14: Summit Products | C14: =Comps_Raw!C13*Comps_Raw!D13 -> 2698.38 | D14: =C14+Comps_Raw!F13+Comps_Raw!G13+Comps_Raw!H13-Comps_Raw!E13 -> 2981.38 | E14: =D14/Comps_Raw!J13 -> 3.34573 | F14: =D14/Comps_Raw!K13 -> 3.1244812 | G14: =D14/Comps_Raw!M13 -> 16.39923 | H14: =D14/Comps_Raw!N13 -> 15.095595 | I14: =D14/Comps_Raw!P13 -> 20.350717 | J14: =D14/Comps_Raw!Q13 -> 18.621986
B15: STATISTIQUES
B16: Minimum | E16: =MIN(E7:E14) -> 1.1929759 | F16: =MIN(F7:F14) -> 1.1869888 | G16: =MIN(G7:G14) -> 8.227261 | H16: =MIN(H7:H14) -> 8.4784918 | I16: =MIN(I7:I14) -> 11.927531 | J16: =MIN(J7:J14) -> 12.492175
B17: 1er quartile | E17: =QUARTILE.INC(E7:E14,1) -> 1.9735162 | F17: =QUARTILE.INC(F7:F14,1) -> 1.9046291 | G17: =QUARTILE.INC(G7:G14,1) -> 11.441453 | H17: =QUARTILE.INC(H7:H14,1) -> 10.881477 | I17: =QUARTILE.INC(I7:I14,1) -> 14.962409 | J17: =QUARTILE.INC(J7:J14,1) -> 13.930372
B18: Médiane | E18: =MEDIAN(E7:E14) -> 2.2413609 | F18: =MEDIAN(F7:F14) -> 2.1350049 | G18: =MEDIAN(G7:G14) -> 12.174714 | H18: =MEDIAN(H7:H14) -> 11.405309 | I18: =MEDIAN(I7:I14) -> 16.07641 | J18: =MEDIAN(J7:J14) -> 15.103878
B19: 3e quartile | E19: =QUARTILE.INC(E7:E14,3) -> 2.6322646 | F19: =QUARTILE.INC(F7:F14,3) -> 2.4915165 | G19: =QUARTILE.INC(G7:G14,3) -> 13.821814 | H19: =QUARTILE.INC(H7:H14,3) -> 12.863629 | I19: =QUARTILE.INC(I7:I14,3) -> 17.721003 | J19: =QUARTILE.INC(J7:J14,3) -> 16.347949
B20: Maximum | E20: =MAX(E7:E14) -> 3.34573 | F20: =MAX(F7:F14) -> 3.1244812 | G20: =MAX(G7:G14) -> 16.39923 | H20: =MAX(H7:H14) -> 15.095595 | I20: =MAX(I7:I14) -> 20.350717 | J20: =MAX(J7:J14) -> 18.64617
B22: VALORISATION IMPLICITE D'ATLAS — EV/EBITDA FY27E
B23: EBITDA FY27E d'Atlas | D23: =Atlas_Raw!G8 -> 172.1
B24: × Médiane EV/EBITDA FY27E = Enterprise value implicite | D24: =D23*H18 -> 1962.8536
B25: − Dette financière brute | D25: =-Atlas_Raw!C18 -> -315
B26: − Dettes de loyers | D26: =-Atlas_Raw!C19 -> -84.5
B27: − Intérêts minoritaires | D27: =-Atlas_Raw!C20 -> -22
B28: + Trésorerie | D28: =Atlas_Raw!C17 -> 68.4
B29: = Equity value implicite | D29: =SUM(D24:D28) -> 1609.7536
B30: ÷ Actions diluées (m) | D30: =Atlas_Raw!C21 -> 48.6
B31: = Prix par action implicite (€) | D31: =D29/D30 -> 33.122503
B32: Prix implicite au 1er quartile (€) | D32: =(D23*H17+SUM(D25:D28))/D30 -> 31.267535
B33: Prix implicite au 3e quartile (€) | D33: =(D23*H19+SUM(D25:D28))/D30 -> 38.286637
B36: Rappel : un comparable peut sembler décoté pour de bonnes raisons. Regarde la croissance et la marge avant de conclure.

Sheet DCF
B2: DCF — FLUX DE TRÉSORERIE DISPONIBLES NON LEVIERS
B3: EUR en millions · convention mi-année · valeur terminale par Gordon
B6: HYPOTHÈSES DE COÛT DU CAPITAL
B7: Taux sans risque | D7: 0.032
B8: Prime de risque actions | D8: 0.065
B9: Beta | D9: 1.12
B10: Coût de la dette avant impôt | D10: 0.05
B11: Taux d'impôt | D11: 0.26
B12: Poids de la dette | D12: 0.3
B13: Poids des capitaux propres | D13: 0.7
B15: Coût des capitaux propres (CAPM) | D15: =D7+D9*D8 -> 0.1048
B16: WACC | D16: =D15*D13+D10*(1-D11)*D12 -> 0.08446
B17: Croissance à l'infini (g) | D17: 0.025
B20: PROJECTION DES FLUX
B21: Exercice | D21: FY26E | E21: FY27E | F21: FY28E | G21: FY29E | H21: FY30E
B22: Chiffre d'affaires | D22: =Atlas_Raw!F6 -> 892 | E22: =Atlas_Raw!G6 -> 945.5 | F22: =Atlas_Raw!H6 -> 996 | G22: =Atlas_Raw!I6 -> 1041 | H22: =Atlas_Raw!J6 -> 1082.6
B23: Croissance (%) | D23: =D22/Atlas_Raw!E6-1 -> 0.060389919 | E23: =E22/D22-1 -> 0.059977578 | F23: =F22/E22-1 -> 0.053410894 | G23: =G22/F22-1 -> 0.045180723 | H23: =H22/G22-1 -> 0.039961575
B24: EBITDA | D24: =Atlas_Raw!F8 -> 158.8 | E24: =Atlas_Raw!G8 -> 172.1 | F24: =Atlas_Raw!H8 -> 184.3 | G24: =Atlas_Raw!I8 -> 194.7 | H24: =Atlas_Raw!J8 -> 204.6
B25: Marge d'EBITDA (%) | D25: =D24/D22 -> 0.17802691 | E25: =E24/E22 -> 0.1820201 | F25: =F24/F22 -> 0.18504016 | G25: =G24/G22 -> 0.1870317 | H25: =H24/H22 -> 0.18898947
B26: D&A | D26: =Atlas_Raw!F10 -> 34.8 | E26: =Atlas_Raw!G10 -> 36.9 | F26: =Atlas_Raw!H10 -> 38.8 | G26: =Atlas_Raw!I10 -> 40.6 | H26: =Atlas_Raw!J10 -> 42.2
B27: EBIT | D27: =D24-D26 -> 124 | E27: =E24-E26 -> 135.2 | F27: =F24-F26 -> 145.5 | G27: =G24-G26 -> 154.1 | H27: =H24-H26 -> 162.4
B28: Impôt sur l'EBIT | D28: =-D27*$D$11 -> -32.24 | E28: =-E27*$D$11 -> -35.152 | F28: =-F27*$D$11 -> -37.83 | G28: =-G27*$D$11 -> -40.066 | H28: =-H27*$D$11 -> -42.224
B29: NOPAT | D29: =D27+D28 -> 91.76 | E29: =E27+E28 -> 100.048 | F29: =F27+F28 -> 107.67 | G29: =G27+G28 -> 114.034 | H29: =H27+H28 -> 120.176
B30: = UFCF | D30: =D29+D31+D32+D33 -> 83.96 | E30: =E29+E31+E32+E33 -> 91.848 | F30: =F29+F31+F32+F33 -> 99.57 | G30: =G29+G31+G32+G33 -> 106.434 | H30: =H29+H31+H32+H33 -> 112.676
B31: + D&A | D31: =D26 -> 34.8 | E31: =E26 -> 36.9 | F31: =F26 -> 38.8 | G31: =G26 -> 40.6 | H31: =H26 -> 42.2
B32: − Capex | D32: =-Atlas_Raw!F12 -> -37.5 | E32: =-Atlas_Raw!G12 -> -39.7 | F32: =-Atlas_Raw!H12 -> -41.8 | G32: =-Atlas_Raw!I12 -> -43.7 | H32: =-Atlas_Raw!J12 -> -45.5
B33: − Variation du BFR | D33: =-Atlas_Raw!F13 -> -5.1 | E33: =-Atlas_Raw!G13 -> -5.4 | F33: =-Atlas_Raw!H13 -> -5.1 | G33: =-Atlas_Raw!I13 -> -4.5 | H33: =-Atlas_Raw!J13 -> -4.2
B34: Période d'actualisation (mi-année) | D34: 0.5 | E34: 1.5 | F34: 2.5 | G34: 3.5 | H34: 4.5
B35: Facteur d'actualisation | D35: =1/(1+$D$16)^D34 -> 0.96026971 | E35: =1/(1+$D$16)^E34 -> 0.88548191 | F35: =1/(1+$D$16)^F34 -> 0.81651874 | G35: =1/(1+$D$16)^G34 -> 0.75292656 | H35: =1/(1+$D$16)^H34 -> 0.69428707
B36: PV de l'UFCF | D36: =D30*D35 -> 80.624245 | E36: =E30*E35 -> 81.329742 | F36: =F30*F35 -> 81.300771 | G36: =G30*G35 -> 80.136986 | H36: =H30*H35 -> 78.22949
B39: VALEUR TERMINALE ET VALORISATION
B40: Somme des PV des UFCF | D40: =SUM(D36:H36) -> 401.62123
B41: PV de la valeur terminale | D41: =(H30*(1+$D$17)/($D$16-$D$17))/(1+$D$16)^4.5 -> 1348.5575
B42: = Enterprise value | D42: =D40+D41 -> 1750.1787
B43: − Dette financière brute | D43: =-Atlas_Raw!C18 -> -315
B44: − Dettes de loyers | D44: =-Atlas_Raw!C19 -> -84.5
B45: − Intérêts minoritaires | D45: =-Atlas_Raw!C20 -> -22
B46: + Trésorerie | D46: =Atlas_Raw!C17 -> 68.4
B47: = Equity value | D47: =SUM(D42:D46) -> 1397.0787
B48: ÷ Actions diluées (m) | D48: =Atlas_Raw!C21 -> 48.6
...

Sheet Valuation_Summary
B2: SYNTHÈSE DE VALORISATION
B3: Prix par action implicite (€)
B6: Méthode | C6: Bas | D6: Central | E6: Haut
B7: Comparables boursiers (EV/EBITDA FY27E) | C7: =Trading_Comps!D32 -> 31.267535 | D7: =Trading_Comps!D31 -> 33.122503 | E7: =Trading_Comps!D33 -> 38.286637
B8: DCF (WACC × croissance à l'infini) | C8: =MIN(DCF!D55:H59) -> 20.355606 | D8: =DCF!D49 -> 28.746476 | E8: =MAX(DCF!D55:H59) -> 44.505811
B10: Fourchette illustrative retenue | C10: =MIN(C7:C8) -> 20.355606 | E10: =MAX(E7:E8) -> 44.505811
B13: Les fourchettes de valorisation sont des résultats d'analyse, pas des valeurs de marché objectives.
B14: Les méthodes ne convergent pas mécaniquement : l'écart entre comparables et DCF est une information, pas une erreur à corriger. Le choix de la fourchette relève du jugement, et doit être argumenté.

Sheet Checks
B2: CONTRÔLES DU MODÈLE
B5: Contrôle | C5: Attendu | D5: Résultat
B6: Bridge comps : EV − dettes + trésorerie = equity | C6: VRAI | D6: =ROUND(Trading_Comps!D24+Trading_Comps!D25+Trading_Comps!D26+Trading_Comps!D27+Trading_Comps!D28-Trading_Comps!D29,1)=0 -> TRUE
B7: Bridge DCF : EV − dettes + trésorerie = equity | C7: VRAI | D7: =ROUND(DCF!D42+DCF!D43+DCF!D44+DCF!D45+DCF!D46-DCF!D47,1)=0 -> TRUE
B8: Croissance à l'infini < WACC | C8: VRAI | D8: =DCF!D17<DCF!D16 -> TRUE
B9: Nombre d'actions strictement positif | C9: VRAI | D9: =Atlas_Raw!C21>0 -> TRUE
B10: Aucune erreur dans les multiples de comps | C10: VRAI | D10: =NOT(ISERROR(SUM(Trading_Comps!E7:J14))) -> TRUE
B11: Aucune erreur dans les flux du DCF | C11: VRAI | D11: =NOT(ISERROR(SUM(DCF!D30:H30))) -> TRUE
B12: Statistiques de comps renseignées | C12: VRAI | D12: =COUNT(Trading_Comps!E16:J20)=30 -> TRUE
B13: Table de sensibilité renseignée | C13: VRAI | D13: =COUNT(DCF!D55:H59)=25 -> TRUE
B14: EV du DCF strictement positive | C14: VRAI | D14: =DCF!D42>0 -> TRUE
B15: Prix par action du DCF cohérent (> 0) | C15: VRAI | D15: =DCF!D49>0 -> TRUE
B18: MODEL CHECK | D18: =IF(AND(D6:D15),"OK","À CORRIGER") -> OK
B20: MODEL CHECK doit afficher OK avant tout envoi. Un contrôle rouge signifie que le modèle n'est pas prêt.

Sheet _LAB_META
A1: case_id | B1: project_atlas_v1
A2: case_version | B2: 1.1.0
A3: grader_version | B3: 1.2
A4: variant | B4: solution
A5: required_named_ranges | B5: ATLAS_MARKET_CAP_NOVA,ATLAS_EV_NOVA,ATLAS_COMPS_MEDIAN_EV_EBITDA_27,ATLAS_IMPLIED_EV_COMPS,ATLAS_IMPLIED_EQUITY_COMPS,ATLAS_IMPLIED_PRICE_COMPS,ATLAS_WACC,ATLAS_UFCF_26,ATLAS_UFCF_27,ATLAS_UFCF_28,ATLAS_UFCF_29,ATLAS_UFCF_30,ATLAS_DCF_PV_FCF,ATLAS_DCF_PV_TV,ATLAS_DCF_EV,ATLAS_DCF_EQUITY,ATLAS_DCF_PRICE,ATLAS_MODEL_CHECK
